Workbook

Sheet B1装修管控总表（优化版）
A1: 商铺号 | C1: 商铺名称 | D1: 面积㎡ | E1: 招商拉群对接 | F1: 运营对接人 | G1: 围挡搭建 | H1: 合作意向确认 | I1: 是否给到红线 | J1: 合同约定接铺时间 | K1: 预计进场时间 | L1: 是否进场 | M1: 实际接铺时间 | N1: 平面图预计出图时间 | O1: 效果图预计出图时间 | P1: 施工图预计出图时间 | Q1: 平面图实际出图时间 | R1: 效果图实际出图实际 | S1: 施工图实际出图时间 | T1: 施工保险 | U1: 门头施工交底 | V1: 营业执照是否取得 | W1: 食品经营许可证取得 | X1: 消防改造是否完成 | Y1: 空调改造是否完成 | Z1: 闭水验收 | AA1: 隐蔽验收 | AB1: 合同约定开业日期 | AC1: 预计开业时间 | AD1: 提前开业天数 | AE1: 提前开业租金 | AF1: 目前施工状态
A2: 改造后-超市区域 | B2: A栋-B1-40 | C2: 树夏 | D2: 100.12
B3: A栋-B1-41 | C3: OPPO | D3: 110.91 | E3: 是 | F3: 宫笑 | I3: 是 | K3: 7.5 | L3: 否 | N3: 6.5 | O3: 6.12 | P3: 6.18
B4: A栋-B1-42 | C4: VIVO | D4: 66.49 | E4: 是 | F4: 宫笑 | I4: 是 | K4: 7.5 | L4: 否 | N4: 6.5 | O4: 6.12 | P4: 6.18
B5: A栋-B1-43 | C5: 同方药业 | D5: 71.7 | E5: 是 | F5: 冷娜 | I5: 是 | K5: 7.5 | L5: 否 | N5: 6.2 | O5: 6.11 | P5: 6.15 | R5: 是
B6: A栋-B1-45 | C6: 诺特兰德 | D6: 64.83
B7: A栋-B1-46 | C7: 科大讯飞 | D7: 64.83 | H7: 5.28
B8: A栋-B1-47 | C8: 洗脸猫 | D8: 67.58 | E8: 是 | F8: 冷娜 | I8: 是 | K8: 7.5 | L8: 否 | N8: 已出图调整修改中 | O8: 6.11 | P8: 6.15 | Q8: 是
B9: A栋-B1-48 | C9: 卡游 | D9: 75.07
B10: A栋-B1-49 | C10: 宠有家 | D10: 135.41 | E10: 是 | F10: 薛洁 | I10: 是 | K10: 7.5 | L10: 否
B11: A栋-B1-50 | C11: 宠有家 | D11: 48.75 | E11: 是 | F11: 薛洁 | I11: 是 | K11: 7.5 | L11: 否
B12: A-B1-Z01 | C12: 超市 | D12: 3836.72 | E12: 是 | F12: 孟祥臻 | I12: 是 | K12: 7.5 | L12: 否 | N12: 6.2（第一版已出） | O12: 6.11 | P12: 6.18
A13: 改造后-中岛 | B13: A栋-B1-53 | C13: SKG-营运外摆 | D13: 23.44
B14: A栋-B1-54 | C14: 添可-营运外摆 | D14: 17.85
B15: A栋-B1-55 | C15: DYSON-营运外摆 | D15: 17.85
B16: A栋-B1-56 | C16: 李山山茶室 | D16: 16.52
B17: A栋-B1-57 | C17: 李山山外摆 | D17: 17.72
B18: A栋-B1-58 | C18: 琦王花生 | D18: 11.33 | E18: 是 | F18: 许如邯 | L18: 否
B19: A栋-B1-59 | C19: 薛记 | D19: 11.33 | E19: 是 | F19: 孟祥臻 | L19: 否
B20: A栋-B1-60 | C20: 目光眼镜 | D20: 22.28 | E20: 是 | F20: 冷娜 | K20: 7.10 | L20: 否 | N20: 已出图审核中 | O20: 已出图审核中 | P20: 6.15 | Q20: 5.29 | R20: 5.29
B21: A栋-B1-61 | C21: 膜壳先锋 | D21: 11.7 | E21: 否 | F21: 冷娜
B22: A栋-B1-62 | C22: 瑞幸外摆 | D22: 10.73 | E22: 6.15 | F22: 张潇 | L22: 否
B23: A栋-B1-63 | C23: 罗曼林 | D23: 13.65
B24: A栋-B1-64 | C24: 德菲梵 | D24: 13.65
B25: A栋-B1-65 | C25: 名之屋 | D25: 16.74
B26: A栋-B1-66 | C26: 柑啵啵 | D26: 15.3
B27: A栋-B1-67 | C27: 有堂古 | D27: 16.24
B28: A栋-B1-68 | C28: 鲜目录寿司 | D28: 14.8
B29: A栋-B1-69 | C29: 德菲凡 | D29: 12.4
B30: A栋-B1-70 | C30: 果小铺 | D30: 15.2
B31: A栋-B1-71 | C31: 周黑鸭 | D31: 12.9 | E31: 是 | F31: 孟祥臻 | H31: 5.31 | K31: 7.2 | L31: 否 | N31: 6.15 | O31: 6.21 | P31: 7.1
B32: A栋-B1-72 | C32: 琴岛留香 | D32: 15.38 | E32: 是 | F32: 孟祥臻 | H32: 5.31 | K32: 7.2 | L32: 否 | N32: 6.15 | O32: 6.21 | P32: 7.1
B33: A栋-B1-73 | C33: 巧克叔叔 | D33: 17.51
B34: A栋-B1-74 | C34: 糖小妙 | D34: 17.83
B35: A栋-B1-75 | C35: fufuland | D35: 17.83
B36: A栋-B1-76 | C36: 茉酸奶 | D36: 37.22
A37: 改造后-边铺 | B37: A栋-B1-01 | C37: 比木.卡西西 | D37: 142.42
B38: A栋-B1-02 | C38: 嗨嗨儿 | D38: 119.87 | E38: / | F38: /
B39: A栋-B1-03 | C39: 犟骨头超级排骨饭 | D39: 62.56 | E39: 是 | F39: 孟祥臻 | K39: 6.16 | L39: 否 | N39: 6.5 | O39: 6.6 | P39: 6.14
B40: A栋-B1-05 | C40: 品秦川 | D40: 148.01 | E40: 是 | F40: 孟祥臻 | K40: 6.16 | L40: 否 | N40: 6.5 | O40: 6.1
...

Sheet 改造后B1招商预签品牌
A1: 改造后—超市区域
A2: 品牌 | B2: 资源号 | C2: 面积 | D2: 保底租金单价 | E2: 物管单价 | F2: 推广费单价 | K2: 全含 | L2: 月总租费，不含抽成 | M2: 月总租费，含抽成 | P2: 月总租费，含抽成 | Q2: 年总租费（含税，元）
C3: （平方米） | D3: （含税，元/平方米/月） | E3: （含税，元/平方米/月） | F3: （含税，元/平方米/月） | G3: 扣点 | H3: 取高临界值 | I3: 保守预估 | J3: 保守 | N3: 激进预估 | O3: 激进抽成 | R3: 保底租金 | S3: 物业 | T3: 推广
A4: oppo | B4: A栋-B1-40 | C4: 98.14 | D4: 130 | E4: 50 | F4: 10.6 | G4: 0.05 | H4: ==D4*C4/G4/1.09 -> 234095.41 | I4: 120000 | J4: ==(I4-H4)*G4*1.09 -> -6218.2 | K4: ==D4+E4+F4 -> 190.6 | L4: ==(D4+E4+F4)*C4 -> 18705.484 | M4: ==K4*C4+MAX(J4,0) -> 18705.484 | N4: 150000 | O4: ==(N4-H4)*G4*1.09 -> -4583.2 | P4: ==K4*C4+MAX(O4,0) -> 18705.484 | Q4: ==M4*12 -> 224465.81 | R4: ==C4*D4 -> 12758.2 | S4: ==E4*C4 -> 4907 | T4: ==F4*C4 -> 1040.284
A5: VIVO | B5: A栋-B1-41 | C5: 115.82 | D5: 120 | E5: 50 | F5: 10.6 | G5: 0.05 | H5: ==D5*C5/G5/1.09 -> 255016.51 | I5: 120000 | J5: ==(I5-H5)*G5*1.09 -> -7358.4 | K5: ==D5+E5+F5 -> 180.6 | L5: ==(D5+E5+F5)*C5 -> 20917.092 | M5: ==K5*C5+MAX(J5,0) -> 20917.092 | N5: 150000 | O5: ==(N5-H5)*G5*1.09 -> -5723.4 | P5: ==K5*C5+MAX(O5,0) -> 20917.092 | Q5: ==M5*12 -> 251005.1 | R5: ==C5*D5 -> 13898.4 | S5: ==E5*C5 -> 5791 | T5: ==F5*C5 -> 1227.692
A6: JINS | B6: A栋-B1-42 | C6: 69.45 | D6: 160 | E6: 50 | F6: 10.6 | G6: 0.11 | H6: ==D6*C6/G6/1.09 -> 92677.231 | I6: 75000 | J6: ==(I6-H6)*G6*1.09 -> -2119.5 | K6: ==D6+E6+F6 -> 220.6 | L6: ==(D6+E6+F6)*C6 -> 15320.67 | M6: ==K6*C6+MAX(J6,0) -> 15320.67 | N6: 100000 | O6: ==(N6-H6)*G6*1.09 -> 878 | P6: ==K6*C6+MAX(O6,0) -> 16198.67 | Q6: ==M6*12 -> 183848.04 | R6: ==C6*D6 -> 11112 | S6: ==E6*C6 -> 3472.5 | T6: ==F6*C6 -> 736.17
A7: 伽百利 | B7: A栋-B1-43 | C7: 74.61 | D7: 145 | E7: 50 | F7: 10.6 | G7: 0.11 | H7: ==D7*C7/G7/1.09 -> 90228.941 | I7: 75000 | J7: ==(I7-H7)*G7*1.09 -> -1825.95 | K7: ==D7+E7+F7 -> 205.6 | L7: ==(D7+E7+F7)*C7 -> 15339.816 | M7: ==K7*C7+MAX(J7,0) -> 15339.816 | N7: 100000 | O7: ==(N7-H7)*G7*1.09 -> 1171.55 | P7: ==K7*C7+MAX(O7,0) -> 16511.366 | Q7: ==M7*12 -> 184077.79 | R7: ==C7*D7 -> 10818.45 | S7: ==E7*C7 -> 3730.5 | T7: ==F7*C7 -> 790.866
A8: 科大讯飞 | B8: A栋-B1-45 | C8: 68.63 | D8: 155 | E8: 50 | F8: 10.6 | G8: 0.11 | H8: ==D8*C8/G8/1.09 -> 88721.018 | I8: 80000 | J8: ==(I8-H8)*G8*1.09 -> -1045.65 | K8: ==D8+E8+F8 -> 215.6 | L8: ==(D8+E8+F8)*C8 -> 14796.628 | M8: ==K8*C8+MAX(J8,0) -> 14796.628 | N8: 80000 | O8: ==(N8-H8)*G8*1.09 -> -1045.65 | P8: ==K8*C8+MAX(O8,0) -> 14796.628 | Q8: ==M8*12 -> 177559.54 | R8: ==C8*D8 -> 10637.65 | S8: ==E8*C8 -> 3431.5 | T8: ==F8*C8 -> 727.478
A9: 联想 | B9: A栋-B1-46 | C9: 66.83 | D9: 155 | E9: 50 | F9: 10.6 | G9: 0.05 | H9: ==D9*C9/G9/1.09 -> 190066.97 | I9: 120000 | J9: ==(I9-H9)*G9*1.09 -> -3818.65 | K9: ==D9+E9+F9 -> 215.6 | L9: ==(D9+E9+F9)*C9 -> 14408.548 | M9: ==K9*C9+MAX(J9,0) -> 14408.548 | N9: 150000 | O9: ==(N9-H9)*G9*1.09 -> -2183.65 | P9: ==K9*C9+MAX(O9,0) -> 14408.548 | Q9: ==M9*12 -> 172902.58 | R9: ==C9*D9 -> 10358.65 | S9: ==E9*C9 -> 3341.5 | T9: ==F9*C9 -> 708.398
A10: HIIDOLL | B10: A栋-B1-47 | C10: 72.95 | D10: 155 | E10: 50 | F10: 10.6 | G10: 0.05 | H10: ==D10*C10/G10/1.09 -> 207472.48 | I10: 120000 | J10: ==(I10-H10)*G10*1.09 -> -4767.25 | K10: ==D10+E10+F10 -> 215.6 | L10: ==(D10+E10+F10)*C10 -> 15728.02 | M10: ==K10*C10+MAX(J10,0) -> 15728.02 | N10: 140000 | O10: ==(N10-H10)*G10*1.09 -> -3677.25 | P10: ==K10*C10+MAX(O10,0) -> 15728.02 | Q10: ==M10*12 -> 188736.24 | R10: ==C10*D10 -> 11307.25 | S10: ==E10*C10 -> 3647.5 | T10: ==F10*C10 -> 773.27
A11: UMUYCASE | B11: A栋-B1-48 | C11: 77.36 | D11: 120 | E11: 50 | F11: 10.6 | G11: 0.11 | H11: ==D11*C11/G11/1.09 -> 77424.52 | I11: 80000 | J11: ==(I11-H11)*G11*1.09 -> 308.8 | K11: ==D11+E11+F11 -> 180.6 | L11: ==(D11+E11+F11)*C11 -> 13971.216 | M11: ==K11*C11+MAX(J11,0) -> 14280.016 | N11: 80000 | O11: ==(N11-H11)*G11*1.09 -> 308.8 | P11: ==K11*C11+MAX(O11,0) -> 14280.016 | Q11: ==M11*12 -> 171360.19 | R11: ==C11*D11 -> 9283.2 | S11: ==E11*C11 -> 3868 | T11: ==F11*C11 -> 820.016
A12: 九木杂物社 | B12: A栋-B1-49 | C12: 131.8 | D12: 105 | E12: 50 | F12: 10.6 | G12: 0.1 | H12: ==D12*C12/G12/1.09 -> 126963.3 | I12: 160000 | J12: ==(I12-H12)*G12*1.09 -> 3601 | K12: ==D12+E12+F12 -> 165.6 | L12: ==(D12+E12+F12)*C12 -> 21826.08 | M12: ==K12*C12+MAX(J12,0) -> 25427.08 | N12: 160000 | O12: ==(N12-H12)*G12*1.09 -> 3601 | P12: ==K12*C12+MAX(O12,0) -> 25427.08 | Q12: ==M12*12 -> 305124.96 | R12: ==C12*D12 -> 13839 | S12: ==E12*C12 -> 6590 | T12: ==F12*C12 -> 1397.08
A13: IP潮玩星球 | B13: A栋-B1-50 | C13: 50.44 | D13: 160 | E13: 50 | F13: 10.6 | G13: 0.11 | H13: ==D13*C13/G13/1.09 -> 67309.425 | I13: 80000 | J13: ==(I13-H13)*G13*1.09 -> 1521.6 | K13: ==D13+E13+F13 -> 220.6 | L13: ==(D13+E13+F13)*C13 -> 11127.064 | M13: ==K13*C13+MAX(J13,0) -> 12648.664 | N13: 80000 | O13: ==(N13-H13)*G13*1.09 -> 1521.6 | P13: ==K13*C13+MAX(O13,0) -> 12648.664 | Q13: ==M13*12 -> 151783.97 | R13: ==C13*D13 -> 8070.4 | S13: ==E13*C13 -> 2522 | T13: ==F13*C13 -> 534.664
A14: 超市 | B14: A-B1-Z01 | C14: 3836.72 | D14: 31.5 | E14: 5.25 | G14: 0.02 | I14: 4000000 | K14: ==D14+E14+F14 -> 36.75 | L14: ==(D14+E14+F14)*C14 -> 140999.46 | M14: ==K14*C14+MAX(J14,0) -> 140999.46 | N14: 4000000 | P14: ==K14*C14+MAX(O14,0) -> 140999.46 | Q14: ==M14*12 -> 1691993.5 | R14: ==C14*D14 -> 120856.68 | S14: ==E14*C14 -> 20142.78 | T14: ==F14*C14 -> 0
A15: 合计 | C15: ==SUM(C4:C14) -> 4662.75 | D15: ==R15/C15 -> 49.957617 | E15: ==S15/C15 -> 13.177691 | F15: ==T15/C15 -> 1.8778442 | J15: ==SUMIF(J4:J14,">0") -> 5431.4 | K15: ==M15/C15 -> 66.178002 | M15: ==SUM(M4:M14) -> 308571.48 | O15: ==SUMIF(O4:O14,">0") -> 7480.95 | P15: ==SUM(P4:P14) -> 310621.03 | Q15: ==SUM(Q4:Q14) -> 3702857.7 | R15: ==SUM(R3:R14) -> 232939.88 | S15: ==SUM(S3:S14) -> 61444.28 | T15: ==SUM(T3:T14) -> 8755.918
J16: ==J15/C15 -> 1.1648491 | O16: ==O15/C15 -> 1.6044073 | P16: ==P15/C15 -> 66.61756
A17: 改造后—中岛区域
A18: 品牌 | B18: 资源号 | C18: 面积 | D18: 保底租金单价 | E18: 物管单价 | F18: 推广费单价 | K18: 全含 | L18: 月总租费，不含抽成 | M18: 月总租费，含抽成 | P18: 月总租费，含抽成 | Q18: 年总租费（含税，元）
C19: （平方米） | D19: （含税，元/平方米/月） | E19: （含税，元/平方米/月） | F19: （含税，元/平方米/月） | G19: 扣点 | H19: 取高临界值 | I19: 保守预估 | J19: 保守 | N19: 激进预估 | O19: 激进抽成 | R19: 保底租金 | S19: 物业 | T19: 推广
A20: SKG | B20: A栋-B1-53 | C20: 23.44 | D20: 250 | E20: 50 | F20: 10.6 | G20: 0.11 | H20: ==D20*C20/G20/1.09 -> 48874.062 | I20: 65000 | J20: ==(I20-H20)*G20*1.09 -> 1933.5 | K20: ==D20+E20+F20 -> 310.6 | L20: ==(D20+E20+F20)*C20 -> 7280.464 | M20: ==K20*C20+MAX(J20,0) -> 9213.964 | N20: 80000 | O20: ==(N20-H20)*G20*1.09 -> 3732 | P20: ==K20*C20+MAX(O20,0) -> 11012.464 | Q20: ==M20*12 -> 110567.57 | R20: ==C20*D20 -> 5860 | S20: ==E20*C20 -> 1172 | T20: ==F20*C20 -> 248.464
A21: 添可 | B21: A栋-B1-55 | C21: 17.85 | D21: 250 | E21: 50 | F21: 10.6 | G21: 0.11 | H21: ==D21*C21/G21/1.09 -> 37218.515 | I21: 65000 | J21: ==(I21-H21)*G21*1.09 -> 3331 | K21: ==D21+E21+F21 -> 310.6 | L21: ==(D21+E21+F21)*C21 -> 5544.21 | M21: ==K21*C21+MAX(J21,0) -> 8875.21 | N21: 80000 | O21: ==(N21-H21)*G21*1.09 -> 5129.5 | P21: ==K21*C21+MAX(O21,0) -> 10673.71 | Q21: ==M21*12 -> 106502.52 | R21: ==C21*D21 -> 4462.5 | S21: ==E21*C21 -> 892.5 | T21: ==F21*C21 -> 189.21
A22: DYSON | B22: A栋-B1-56 | C22: 17.85 | D22: 250 | E22: 50 | F22: 10.6 | G22: 0.11 | H22: ==D22*C22/G22/1.09 -> 37218.515 | I22: 65000 | J22: ==(I22-H22)*G22*1.09 -> 3331 | K22: ==D22+E22+F22 -> 310.6 | L22: ==(D22+E22+F22)*C22 -> 5544.21 | M22: ==K22*C22+MAX(J22,0) -> 8875.21 | N22: 80000 | O22: ==(N22-H22)*G22*1.09 -> 5129.5 | P22: ==K22*C22+MAX(O22,0) -> 10673.71 | Q22: ==M22*12 -> 106502.52 | R22: ==C22*D22 -> 4462.5 | S22: ==E22*C22 -> 892.5 | T22: ==F22*C22 -> 189.21
A23: 李山山茶室 | B23: A栋-B1-57 | C23: 16.51 | D23: 275 | E23: 50 | F23: 10.6 | G23: 0.12 | H23: ==D23*C23/G23/1.09 -> 34711.391 | I23: 130000 | J23: ==(I23-H23)*G23*1.09 -> 12463.75 | K23: ==D23+E23+F23 -> 335.6 | L23: ==(D23+E23+F23)*C23 -> 5540.756 | M23: ==K23*C23+MAX(J23,0) -> 18004.506 | N23: 80000 | O23: ==(N23-H23)*G23*1.09 -> 5923.75 | P23: ==K23*C23+MAX(O23,0) -> 11464.506 | Q23: ==M23*12 -> 216054.07 | R23: ==C23*D23 -> 4540.25 | S23: ==E23*C23 -> 825.5 | T23: ==F23*C23 -> 175.006
A24: 李山山外摆 | B24: A栋-B1-58 | C24: 17.59 | D24: 275 | E24: 50 | F24: 10.6 | G24: 0 | H24: 0 | I24: 0 | J24: ==(I24-H24)*G24*1.09 -> 0 | K24: ==D24+E24+F24 -> 335.6 | L24: ==(D24+E24+F24)*C24 -> 5903.204 | M24: ==K24*C24+MAX(J24,0) -> 5903.204 | N24: 80000 | O24: ==(N24-H24)*G24*1.09 -> 0 | P24: ==K24*C24+MAX(O24,0) -> 5903.204 | Q24: ==M24*12 -> 70838.448 | R24: ==C24*D24 -> 4837.25 | S24: ==E24*C24 -> 879.5 | T24: ==F24*C24 -> 186.454
A25: moody美瞳 | B25: A栋-B1-59 | C25: 11.33 | D25: 335 | E25: 50 | F25: 10.6 | G25: 0.11 | H25: ==D25*C25/G25/1.09 -> 31655.963 | I25: 40000 | J25: ==(I25-H25)*G25*1.09 -> 1000.45 | K25: ==D25+E25+F25 -> 395.6 | L25: ==(D25+E25+F25)*C25 -> 4482.148 | M25: ==K25*C25+MAX(J25,0) -> 5482.598 | N25: 70000 | O25: ==(N25-H25)*G25*1.09 -> 4597.45 | P25: ==K25*C25+MAX(O25,0) -> 9079.598 | Q25: ==M25*12 -> 65791.176 | R25: ==C25*D25 -> 3795.55 | S25: ==E25*C25 -> 566.5 | T25: ==F25*C25 -> 120.098
A26: 芷甲 | B26: A栋-B1-60 | C26: 11.33 | D26: 335 | E26: 50 | F26: 10.6 | G26: 0.11 | H26: ==D26*C26/G26/1.09 -> 31655.963 | I26: 40000 | J26: ==(I26-H26)*G26*1.09 -> 1000.45 | K26: ==D26+E26+F26 -> 395.6 | L26: ==(D26+E26+F26)*C26 -> 4482.148 | M26: ==K26*C26+MAX(J26,0) -> 5482.598 | N26: 70000 | O26: ==(N26-H26)*G26*1.09 -> 4597.45 | P26: ==K26*C26+MAX(O26,0) -> 9079.598 | Q26: ==M26*12 -> 65791.176 | R26: ==C26*D26 -> 3795.55 | S26: ==E26*C26 -> 566.5 | T26: ==F26*C26 -> 120.098
A27: 结绳记 | B27: A栋-B1-61 | C27: 11.75 | D27: 335 | E27: 50 | F27: 10.6 | G27: 0.11 | H27: ==D27*C27/G27/1.09 -> 32829.441 | I27: 40000 | J27: ==(I27-H27)*G27*1.09 -> 859.75 | K27: ==D27+E27+F27 -> 395.6 | L27: ==(D27+E27+F27)*C27 -> 4648.3 | M27: ==K27*C27+MAX(J27,0) -> 5508.05 | N27: 70000 | O27: ==(N27-H27)*G27*1.09 -> 4456.75 | P27: ==K27*C27+MAX(O27,0) -> 9105.05 | Q27: ==M27*12 -> 66096.6 | R27: ==C27*D27 -> 3936.25 | S27: ==E27*C27 -> 587.5 | T27: ==F27*C27 -> 124.55
A28: 花点时间 | B28: A栋-B1-62 | C28: 10.73 | D28: 335 | E28: 50 | F28: 10.6 | G28: 0.11 | H28: ==D28*C28/G28/1.09 -> 29979.566 | I28: 50000 | J28: ==(I28-H28)*G28*1.09 -> 2400.45 | K28: ==D28+E28+F28 -> 395.6 | L28: ==(D28+E28+F28)*C28 -> 4244.788 | M28: ==K28*C28+MAX(J28,0) -> 6645.238 | N28: 70000 | O28: ==(N28-H28)*G28*1.09 -> 4798.45 | P28: ==K28*C28+MAX(O28,0) -> 9043.238 | Q28: ==M28*12 -> 79742.856 | R28: ==C28*D28 -> 3594.55 | S28: ==E28*C28 -> 536.5 | T28: ==F28*C28 -> 113.738
A29: 酥乾隆外摆 | B29: A栋-B1-63 | C29: 13.65 | D29: 275 | E29: 50 | F29: 10.6 | G29: 0 | H29: 0 | I29: 0 | J29: ==(I29-H29)*G29*1.09 -> 0 | K29: ==D29+E29+F29 -> 335.6 | L29: ==(D29+E29+F29)*C29 -> 4580.94 | M29: ==K29*C29+MAX(J29,0) -> 4580.94 | N29: 76000 | O29: ==(N29-H29)*G29*1.09 -> 0 | P29: ==K29*C29+MAX(O29,0) -> 4580.94 | Q29: ==M29*12 -> 54971.28 | R29: ==C29*D29 -> 3753.75 | S29: ==E29*C29 -> 682.5 | T29: ==F29*C29 -> 144.69
A30: 丹香外摆 | B30: A栋-B1-65 | C30: 13.65 | D30: 275 | E30: 50 | F30: 10.6 | G30: 0 | H30: 0 | I30: 0 | J30: ==(I30-H30)*G30*1.09 -> 0 | K30: ==D30+E30+F30 -> 335.6 | L30: ==(D30+E30+F30)*C30 -> 4580.94 | M30: ==K30*C30+MAX(J30,0) -> 4580.94 | N30: 76000 | O30: ==(N30-H30)*G30*1.09 -> 0 | P30: ==K30*C30+MAX(O30,0) -> 4580.94 | Q30: ==M30*12 -> 54971.28 | R30: ==C30*D30 -> 3753.75 | S30: ==E30*C30 -> 682.5 | T30: ==F30*C30 -> 144.69
A31: 名之屋 | B31: A栋-B1-66 | C31: 16.52 | D31: 335 | E31: 50 | F31: 10.6 | G31: 0.12 | H31: ==D31*C31/G31/1.09 -> 42310.398 | I31: 76000 | J31: ==(I31-H31)*G31*1.09 -> 4406.6 | K31: ==D31+E31+F31 -> 395.6 | L31: ==(D31+E31+F31)*C31 -> 6535.312 | M31: ==K31*C31+MAX(J31,0) -> 10941.912 | N31: 90000 | O31: ==(N31-H31)*G31*1.09 -> 6237.8 | P31: ==K31*C31+MAX(O31,0) -> 12773.112 | Q31: ==M31*12 -> 131302.94 | R31: ==C31*D31 -> 5534.2 | S31: ==E31*C31 -> 826 | T31: ==F31*C31 -> 175.112
A32: 鸡蛋仔 | B32: A栋-B1-67 | C32: 14.47 | D32: 335 | E32: 50 | F32: 10.6 | G32: 0.12 | H32: ==D32*C32/G32/1.09 -> 37060.015 | I32: 76000 | J32: ==(I32-H32)*G32*1.09 -> 5093.35 | K32: ==D32+E32+F32 -> 395.6 | L32: ==(D32+E32+F32)*C32 -> 5724.332 | M32: ==K32*C32+MAX(J32,0) -> 10817.682 | N32: 76000 | O32: ==(N32-H32)*G32*1.09 -> 5093.35 | P32: ==K32*C32+MAX(O32,0) -> 10817.682 | Q32: ==M32*12 -> 129812.18 | R32: ==C32*D32 -> 4847.45 | S32: ==E32*C32 -> 723.5 | T32: ==F32*C32 -> 153.382
A33: 有堂古 | B33: A栋-B1-68 | C33: 16.24 | D33: 335 | E33: 50 | F33: 10.6 | G33: 0.12 | H33: ==D33*C33/G33/1.09 -> 41593.272 | I33: 76000 | J33: ==(I33-H33)*G33*1.09 -> 4500.4 | K33: ==D33+E33+F33 -> 395.6 | L33: ==(D33+E33+F33)*C33 -> 6424.544 | M33: ==K33*C33+MAX(J33,0) -> 10924.944 | N33: 80000 | O33: ==(N33-H33)*G33*1.09 -> 5023.6 | P33: ==K33*C33+MAX(O33,0) -> 11448.144 | Q33: ==M33*12 -> 131099.33 | R33: ==C33*D33 -> 5440.4 | S33: ==E33*C33 -> 812 | T33: ==F33*C33 -> 172.144
A34: 鲜目录寿司 | B34: A栋-B1-69 | C34: 14.8 | D34: 335 | E34: 50 | F34: 10.6 | G34: 0.12 | H34: ==D34*C34/G34/1.09 -> 37905.199 | I34: 76000 | J34: ==(I34-H34)*G34*1.09 -> 4982.8 | K34: ==D34+E34+F34 -> 395.6 | L34: ==(D34+E34+F34)*C34 -> 5854.88 | M34: ==K34*C34+MAX(J34,0) -> 10837.68 | N34: 80000 | O34: ==(N34-H34)*G34*1.09 -> 5506 | P34: ==K34*C34+MAX(O34,0) -> 11360.88 | Q34: ==M34*12 -> 130052.16 | R34: ==C34*D34 -> 4958 | S34: ==E34*C34 -> 740 | T34: ==F34*C34 -> 156.88
A35: 藤田关东煮 | B35: A栋-B1-70 | C35: 12.4 | D35: 335 | E35: 50 | F35: 10.6 | G35: 0.12 | H35: ==D35*C35/G35/1.09 -> 31758.41 | I35: 76000 | J35: ==(I35-H35)*G35*1.09 -> 5786.8 | K35: ==D35+E35+F35 -> 395.6 | L35: ==(D35+E35+F35)*C35 -> 4905.44 | M35: ==K35*C35+MAX(J35,0) -> 10692.24 | N35: 75000 | O35: ==(N35-H35)*G35*1.09 -> 5656 | P35: ==K35*C35+MAX(O35,0) -> 10561.44 | Q35: ==M35*12 -> 128306.88 | R35: ==C35*D35 -> 4154 | S35: ==E35*C35 -> 620 | T35: ==F35*C35 -> 131.44
A36: 李磊与韩梅梅 | B36: A栋-B1-71 | C36: 15.2 | D36: 335 | E36: 50 | F36: 10.6 | G36: 0.12 | H36: ==D36*C36/G36/1.09 -> 38929.664 | I36: 76000 | J36: ==(I36-H36)*G36*1.09 -> 4848.8 | K36: ==D36+E36+F36 -> 395.6 | L36: ==(D36+E36+F36)*C36 -> 6013.12 | M36: ==K36*C36+MAX(J36,0) -> 10861.92 | N36: 80000 | O36: ==(N36-H36)*G36*1.09 -> 5372 | P36: ==K36*C36+MAX(O36,0) -> 11385.12 | Q36: ==M36*12 -> 130343.04 | R36: ==C36*D36 -> 5092 | S36: ==E36*C36 -> 760 | T36: ==F36*C36 -> 161.12
A37: 蒂娜朵拉 | B37: A栋-B1-72 | C37: 12.91 | D37: 335 | E37: 50 | F37: 10.6 | G37: 0.12 | H37: ==D37*C37/G37/1.09 -> 33064.602 | I37: 76000 | J37: ==(I37-H37)*G37*1.09 -> 5615.95 | K37: ==D37+E37+F37 -> 395.6 | L37: ==(D37+E37+F37)*C37 -> 5107.196 | M37: ==K37*C37+MAX(J37,0) -> 10723.146 | N37: 76000 | O37: ==(N37-H37)*G37*1.09 -> 5615.95 | P37: ==K37*C37+MAX(O37,0) -> 10723.146 | Q37: ==M37*12 -> 128677.75 | R37: ==C37*D37 -> 4324.85 | S37: ==E37*C37 -> 645.5 | T37: ==F37*C37 -> 136.846
A38: 糖叙外摆 | B38: A栋-B1-73 | C38: 15.38 | D38: 275 | E38: 50 | F38: 10.6 | G38: 0 | H38: 0 | I38: 0 | J38: ==(I38-H38)*G38*1.09 -> 0 | K38: ==D38+E38+F38 -> 335.6 | L38: ==(D38+E38+F38)*C38 -> 5161.528 | M38: ==K38*C38+MAX(J38,0) -> 5161.528 | N38: 78000 | O38: ==(N38-H38)*G38*1.09 -> 0 | P38: ==K38*C38+MAX(O38,0) -> 5161.528 | Q38: ==M38*12 -> 61938.336 | R38: ==C38*D38 -> 4229.5 | S38: ==E38*C38 -> 769 | T38: ==F38*C38 -> 163.028
A39: 巧克叔叔 | B39: A栋-B1-75 | C39: 17.51 | D39: 335 | E39: 50 | F39: 10.6 | G39: 0.12 | H39: ==D39*C39/G39/1.09 -> 44845.948 | I39: 80000 | J39: ==(I39-H39)*G39*1.09 -> 4598.15 | K39: ==D39+E39+F39 -> 395.6 | L39: ==(D39+E39+F39)*C39 -> 6926.956 | M39: ==K39*C39+MAX(J39,0) -> 11525.106 | N39: 80000 | O39: ==(N39-H39)*G39*1.09 -> 4598.15 | P39: ==K39*C39+MAX(O39,0) -> 11525.106 | Q39: ==M39*12 -> 138301.27 | R39: ==C39*D39 -> 5865.85 | S39: ==E39*C39 -> 875.5 | T39: ==F39*C39 -> 185.606
A40: 糖小妙 | B40: A栋-B1-76 | C40: 17.83 | D40: 335 | E40: 50 | F40: 10.6 | G40: 0.12 | H40: ==D40*C40/G40/1.09 -> 45665.52 | I40: 80000 | J40: ==(I40-H40)*G40*1.09 -> 4490.95 | K40: ==D40+E40+F40 -> 395.6 | L40: ==(D40+E40+F40)*C40 -> 7053.548 | M40: ==K40*C40+MAX(J40,0) -> 11544.498 | N40: 80000 | O40: ==(N40-H40)*G40*1.09 -> 4490.95 | P40: ==K40*C40+MAX(O40,0) -> 11544.498 | Q40: ==M40*12 -> 138533.98 | R40: ==C40*D40 -> 5973.05 | S40: ==E40*C40 -> 891.5 | T40: ==F40*C40 -> 188.998
...
